Workbook

Sheet About
A1: Sales services and processes
A2: Domain: Sales (https://www.insperity.com/ontology/domain-sales/) · Commercial Operations · version 0.1.0 · Draft · author Jeffrey Wallk
A4: What this workbook is
A5: A catalog of the selling process and the services that support it, in the shape of the Sales domain ontology: the selling process (sales:selling-process) broken into six selling stages and their selling steps (sales:selling-step), the services each step uses, the buyer persona job steps each step addresses (core:addresses), and the sales measures. Rows marked In model already exist in the Sales or Commercial Operations taxonomy; rows marked Proposed are candidates for the next build of the Sales spec.
A6: Job steps come from the Client Admin and HR Specialist job studies in KE Workbench › PEO buyer personas. Gray columns are calculated: edit the source columns (Processes › Addresses job steps, Services › Supports process steps) and the counts, matrix and coverage update.
A8: Summary
A9: Selling steps | B9: =COUNTIF(Processes!$F$2:$F$34,"Selling step") -> 26 | C9: Level 2 rows on Processes
A10: in model | B10: =COUNTIFS(Processes!$F$2:$F$34,"Selling step",Processes!$T$2:$T$34,"In model") -> 8 | C10: Exist as concepts in the Sales or Commercial Operations taxonomy
A11: proposed | B11: =COUNTIFS(Processes!$F$2:$F$34,"Selling step",Processes!$T$2:$T$34,"Proposed") -> 18 | C11: Candidates for the next build
A12: Services | B12: =COUNTA(Services!$A$2:$A$27) -> 26
A13: provided by Sales or Sales operations | B13: =COUNTIF(Services!$F$2:$F$27,"Sales")+COUNTIF(Services!$F$2:$F$27,"Sales operations") -> 17
A14: provided by another Commercial Operations domain | B14: =COUNTIF(Services!$C$2:$C$27,"Shared commercial service") -> 9 | C14: Reached through a Commercial Operations shared class, never by referring to the sibling domain (design decision D2)
A15: automated or hybrid | B15: =COUNTIF(Services!$G$2:$G$27,"Automated")+COUNTIF(Services!$G$2:$G$27,"Hybrid") -> 20 | C15: Candidates for agents and decision models
A16: Selling steps with no supporting service | B16: =COUNTIFS(Processes!$F$2:$F$34,"Selling step",Processes!$U$2:$U$34,0) -> 0 | C16: Highlighted on Process × Service
A17: Sales-owned job steps | B17: =COUNTIF('Job steps'!$F$2:$F$29,"Sales") -> 18 | C17: Buyer stages Discover to Decide
A18: covered by in-model steps | B18: =COUNTIFS('Job steps'!$F$2:$F$29,"Sales",'Job steps'!$H$2:$H$29,">0") -> 4
A19: covered once the proposals are added | B19: =COUNTIFS('Job steps'!$F$2:$F$29,"Sales",'Job steps'!$G$2:$G$29,">0") -> 18
A20: value gaps (no step addresses them) | B20: =COUNTIF('Job steps'!$I$2:$I$29,"Value gap") -> 0
A21: Job step coverage, in model | B21: =IF(B17=0,0,B18/B17) -> 0.22222222 | C21: Measure SM-13 today
A22: Job step coverage, with proposals | B22: =IF(B17=0,0,B19/B17) -> 1 | C22: Measure SM-13 once the proposed steps are modeled
A24: Legend
A25: Status | B25: In model: the concept exists in the published taxonomy. Proposed: to be added to spec_sales.py (or the Commercial Operations spec) and rebuilt. Retired: kept for history.
A26: Kind | B26: Process (sales:selling-process) · Selling stage (provider's view of the buyer's journey, Baseline decision 21) · Selling step (sales:selling-step, the process step facts are anchored to).
A27: Delivery mode | B27: Manual: performed by a person. Automated: performed by a digital agent or system. Hybrid: both (Baseline decision 12).
A28: Addresses job steps | B28: core:addresses, intentionally many-to-many. A sales-owned job step that no selling step addresses is a value gap.
A29: IDs | B29: SP processes and steps · SV services · SM measures · JS-CA Client Admin job steps · JS-HR HR Specialist job steps. Separate several IDs with semicolons.
A30: Gray cells | B30: Calculated. Do not type over them.
A32: Modeling findings for the next build
A33: Move census, quote and signature to Commercial Operations | B33: Sales steps consume them, but they are Pricing and contracts primitives. Under D2, a term two domains use belongs in the container.
A34: Move liability and positioning to Commercial Operations | B34: Sales needs liability (Legal) for the employer liability review and positioning (Marketing) for competitive positioning.
A35: Add a "Sales service" top concept | B35: Formalized by core:service and broad-matching core-services "Sales services". The 17 Sales and Sales operations services become its narrower concepts.
A36: New primitives | B36: meeting, presentation, case (business case), reason (win-loss reason).
A37: Stage mismatches to review | B37: HR Specialist "Find where we carry compliance risk today" is a Discover job step but is also addressed by the Qualify step Employer liability review. Per Baseline decision 21, the mismatch is where value gaps form; confirm the stage or the step.

Sheet Processes
A1: ID | B1: Level | C1: Process | D1: Parent | E1: Selling stage | F1: Kind | G1: Definition | H1: Performed by | I1: Delivery mode | J1: Inputs (consumes) | K1: Outputs (produces) | L1: Addresses job steps | M1: Triggered by | N1: Governed by | O1: Measured by | P1: Formalized by (class) | Q1: Taxonomy IRI | R1: Primitives (dcterms:subject) | S1: New primitives needed | T1: Status | U1: Services supporting (calculated)
A2: SP-00 | B2: 0 | C2: Selling process | F2: Process | G2: A process by which the organization pursues an opportunity from discovery to a won or lost decision and the handoff of a won client. | H2: Sales representative | I2: Hybrid | J2: Lead; Account; Ideal customer profile | K2: Opportunity; Proposal; Client service agreement; Booking | M2: Lead conversion | N2: Sales plan; Client service agreement template | O2: Win rate; Sales cycle length; Pipeline coverage | P2: sales:selling-process | Q2: https://www.insperity.com/ontology/domain-sales/selling-process | R2: core-process/process | T2: In model | U2: =COUNTIF(Services!$I$2:$I$200,"*"&A2&"*") -> 0
A3: SP-10 | B3: 1 | C3: Discover | D3: SP-00 | E3: Discover | F3: Selling stage | G3: A selling stage in which the seller learns the prospect's situation, needs and the jobs it is trying to get done. | O3: Stage conversion rate; Time in stage | P3: sales:selling-step | Q3: https://www.insperity.com/taxonomy/domain-sales/discover | R3: core-lifecycle/discover | T3: In model | U3: =COUNTIF(Services!$I$2:$I$200,"*"&A3&"*") -> 0
A4: SP-20 | B4: 1 | C4: Qualify | D4: SP-00 | E4: Qualify | F4: Selling stage | G4: A selling stage in which the seller determines whether the opportunity fits the ideal customer profile and is worth pursuing. | O4: Stage conversion rate; Time in stage | P4: sales:selling-step | Q4: https://www.insperity.com/taxonomy/domain-sales/qualify | R4: domain-commercial-operations/qualification | T4: In model | U4: =COUNTIF(Services!$I$2:$I$200,"*"&A4&"*") -> 0
A5: SP-30 | B5: 1 | C5: Evaluate | D5: SP-00 | E5: Evaluate | F5: Selling stage | G5: A selling stage in which the buyer assesses the organization's offerings against its needs and its alternatives. | O5: Stage conversion rate; Time in stage | P5: sales:selling-step | Q5: https://www.insperity.com/taxonomy/domain-sales/evaluate | R5: core-governance/assessment | T5: In model | U5: =COUNTIF(Services!$I$2:$I$200,"*"&A5&"*") -> 0
A6: SP-40 | B6: 1 | C6: Propose | D6: SP-00 | E6: Propose | F6: Selling stage | G6: A selling stage in which the organization presents a proposal of offerings, terms and prices. | O6: Stage conversion rate; Time in stage | P6: sales:selling-step | Q6: https://www.insperity.com/taxonomy/domain-sales/propose | R6: domain-commercial-operations/proposal | T6: In model | U6: =COUNTIF(Services!$I$2:$I$200,"*"&A6&"*") -> 0
A7: SP-50 | B7: 1 | C7: Decide | D7: SP-00 | E7: Decide | F7: Selling stage | G7: A selling stage in which the buyer negotiates and makes its decision, ending in a win or a loss. | O7: Stage conversion rate; Time in stage | P7: sales:selling-step | Q7: https://www.insperity.com/taxonomy/domain-sales/decide | R7: core-decision/decision | T7: In model | U7: =COUNTIF(Services!$I$2:$I$200,"*"&A7&"*") -> 0
A8: SP-60 | B8: 1 | C8: Onboard | D8: SP-00 | E8: Onboard | F8: Selling stage | G8: A selling stage in which a won client is handed off to be brought into active service. | O8: Stage conversion rate; Time in stage | P8: sales:selling-step | Q8: https://www.insperity.com/taxonomy/domain-sales/onboard | R8: core-event/onboarding | T8: In model | U8: =COUNTIF(Services!$I$2:$I$200,"*"&A8&"*") -> 0
A9: SP-11 | B9: 2 | C9: Prospecting | D9: SP-10 | E9: Discover | F9: Selling step | G9: A selling step that searches the territory for parties that fit the ideal customer profile. | H9: Sales representative | I9: Hybrid | J9: Ideal customer profile; Territory; Intent signal | K9: Lead; Prospect account | M9: Territory plan published | N9: Territory plan; Marketing communication law | O9: Leads created; Prospecting activity | P9: sales:selling-step | Q9: https://www.insperity.com/taxonomy/domain-sales/prospecting | R9: domain-sales/prospecting | T9: In model | U9: =COUNTIF(Services!$I$2:$I$200,"*"&A9&"*") -> 2
A10: SP-12 | B10: 2 | C10: Outreach | D10: SP-10 | E10: Discover | F10: Selling step | G10: A selling step in which the seller contacts a lead that has not asked to be contacted, following a cadence. | H10: Sales representative | I10: Hybrid | J10: Lead; Cadence | K10: Interaction; Meeting request | M10: Lead assigned | N10: Cadence; Telephone consumer protection act; CAN-SPAM act; Consent requirement | O10: Response rate | P10: sales:selling-step | Q10: https://www.insperity.com/taxonomy/domain-sales/outreach | R10: domain-sales/outreach | T10: In model | U10: =COUNTIF(Services!$I$2:$I$200,"*"&A10&"*") -> 2
A11: SP-13 | B11: 2 | C11: Lead acceptance | D11: SP-10 | E11: Discover | F11: Selling step | G11: A selling step in which sales accepts or rejects a marketing-qualified lead, making it a sales-qualified lead. | H11: Sales representative | I11: Hybrid | J11: Marketing-qualified lead; Lead score | K11: Sales-qualified lead; Rejection reason | M11: Marketing-qualified lead handed off | N11: Lead service level agreement | O11: Lead acceptance rate; Speed to lead | P11: sales:selling-step | Q11: https://www.insperity.com/taxonomy/domain-sales/lead-acceptance | R11: domain-commercial-operations/lead; core-process/approval | T11: Proposed | U11: =COUNTIF(Services!$I$2:$I$200,"*"&A11&"*") -> 4
A12: SP-14 | B12: 2 | C12: Discovery meeting | D12: SP-10 | E12: Discover | F12: Selling step | G12: A selling step in which the seller meets the prospect to learn its situation, current human resources setup and pain points. | H12: Sales representative | I12: Manual | J12: Prospect account; Sales-qualified lead | K12: Discovery notes; Account | L12: JS-CA-01; JS-HR-01 | M12: Meeting scheduled | N12: Discovery guide | O12: Meetings held; Discovery-to-qualification rate | P12: sales:selling-step | Q12: https://www.insperity.com/taxonomy/domain-sales/discovery-meeting | R12: core-lifecycle/discover; core-event/interaction | S12: meeting | T12: Proposed | U12: =COUNTIF(Services!$I$2:$I$200,"*"&A12&"*") -> 3
A13: SP-15 | B13: 2 | C13: Jobs and needs capture | D13: SP-10 | E13: Discover | F13: Selling step | G13: A selling step that records the jobs, job steps and desired outcomes the buyer personas at the prospect are trying to get done. | H13: Sales representative | I13: Hybrid | J13: Discovery notes; Buyer persona | K13: Job study (prospect) | L13: JS-CA-01; JS-HR-01 | M13: Discovery meeting completed | N13: Jobs model (Baseline decisions 16–21) | O13: Job steps captured per opportunity | P13: sales:selling-step | Q13: https://www.insperity.com/taxonomy/domain-sales/jobs-and-needs-capture | R13: core-job/study; core-requirements/need | T13: Proposed | U13: =COUNTIF(Services!$I$2:$I$200,"*"&A13&"*") -> 2
A14: SP-21 | B14: 2 | C14: Opportunity qualification | D14: SP-20 | E14: Qualify | F14: Selling step | G14: A selling step that determines whether the prospect fits the ideal customer profile by size, industry and the states it hires in. | H14: Sales representative | I14: Hybrid | J14: Discovery notes; Ideal customer profile; Firmographic profile | K14: Qualification decision | L14: JS-CA-02; JS-HR-02 | M14: Jobs and needs captured | N14: Ideal customer profile; Underwriting guideline (eligibility) | O14: Qualification rate | P14: sales:selling-step | Q14: https://www.insperity.com/taxonomy/domain-commercial-operations/qualification | R14: domain-commercial-operations/qualification | T14: In model | U14: =COUNTIF(Services!$I$2:$I$200,"*"&A14&"*") -> 3
A15: SP-22 | B15: 2 | C15: Employer liability review | D15: SP-20 | E15: Qualify | F15: Selling step | G15: A selling step that inventories the employer liabilities and compliance risks the prospect carries today. | H15: Sales representative | I15: Hybrid | J15: Discovery notes; Prospect's current human resources setup | K15: Liability inventory | L15: JS-CA-11; JS-HR-01 | M15: Qualification started | N15: Employment law; Employee benefits law | O15: Reviews completed | P15: sales:selling-step | Q15: https://www.insperity.com/taxonomy/domain-sales/employer-liability-review | R15: core-role/employer; domain-legal/liability (via container) | S15: liability (move to container) | T15: Proposed | U15: =COUNTIF(Services!$I$2:$I$200,"*"&A15&"*") -> 1
A16: SP-23 | B16: 2 | C16: Opportunity creation | D16: SP-20 | E16: Qualify | F16: Selling step | G16: A selling step that converts a qualified lead into an opportunity and records what sourced it. | H16: Sales representative | I16: Automated | J16: Sales-qualified lead; Qualification decision | K16: Opportunity; Attribution | M16: Qualification passed | N16: Attribution rules; Opportunity registration rules (partners) | O16: Opportunities created; Conversion rate | P16: sales:selling-step | Q16: https://www.insperity.com/taxonomy/domain-commercial-operations/lead-conversion | R16: domain-commercial-operations/lead; domain-commercial-operations/conversion | T16: In model | U16: =COUNTIF(Services!$I$2:$I$200,"*"&A16&"*") -> 4
A17: SP-31 | B17: 2 | C17: Demonstration | D17: SP-30 | E17: Evaluate | F17: Selling step | G17: A selling step that shows the buyer how the services and technology work in use. | H17: Sales representative | I17: Manual | J17: Opportunity; Job study (prospect) | K17: Demonstration feedback | L17: JS-CA-01; JS-HR-03 | M17: Opportunity created | N17: Demonstration script | O17: Demonstrations held | P17: sales:selling-step | Q17: https://www.insperity.com/taxonomy/domain-sales/demonstration | R17: domain-sales/demonstration | T17: In model | U17: =COUNTIF(Services!$I$2:$I$200,"*"&A17&"*") -> 3
A18: SP-32 | B18: 2 | C18: Census collection | D18: SP-30 | E18: Evaluate | F18: Selling step | G18: A selling step that collects the prospect's employee census securely for underwriting and quoting. | H18: Sales representative | I18: Hybrid | J18: Opportunity; Census template | K18: Census | L18: JS-CA-09; JS-CA-14 | M18: Prospect agrees to be quoted | N18: Data protection and retention norms (Legal); Underwriting guideline | O18: Census completeness; Census turnaround time | P18: sales:selling-step | Q18: https://www.insperity.com/taxonomy/domain-sales/census-collection | R18: census (move to container); core-process/inputs | S18: census (move to container) | T18: Proposed | U18: =COUNTIF(Services!$I$2:$I$200,"*"&A18&"*") -> 1
A19: SP-33 | B19: 2 | C19: Total cost of employment comparison | D19: SP-30 | E19: Evaluate | F19: Selling step | G19: A selling step that compares the prospect's all-in cost per employee today with the cost under the organization's offering, now and as headcount grows. | H19: Sales representative | I19: Hybrid | J19: Census; Current costs; Benefits rates | K19: Cost comparison | L19: JS-CA-03; JS-CA-07; JS-CA-08 | M19: Census collected | N19: Pricing model | O19: Comparisons delivered | P19: sales:selling-step | Q19: https://www.insperity.com/taxonomy/domain-sales/total-cost-of-employment-comparison | R19: core-product/cost; core-governance/assessment | T19: Proposed | U19: =COUNTIF(Services!$I$2:$I$200,"*"&A19&"*") -> 2
A20: SP-34 | B20: 2 | C20: Benefits plan comparison | D20: SP-30 | E20: Evaluate | F20: Selling step | G20: A selling step that compares the benefit plans the prospect's employees have today with those they would see. | H20: Sales representative | I20: Hybrid | J20: Census; Current plans; Benefit plan catalog | K20: Benefits comparison | L20: JS-HR-03 | M20: Census collected | N20: Employee benefits law | O20: Comparisons delivered | P20: sales:selling-step | Q20: https://www.insperity.com/taxonomy/domain-sales/benefits-plan-comparison | R20: domain-commercial-operations/benefit; core-product/plan; core-governance/assessment | T20: Proposed | U20: =COUNTIF(Services!$I$2:$I$200,"*"&A20&"*") -> 1
A21: SP-35 | B21: 2 | C21: Competitive positioning | D21: SP-30 | E21: Evaluate | F21: Selling step | G21: A selling step that positions the offering against the competitor or alternative the buyer is considering. | H21: Sales representative | I21: Manual | J21: Opportunity; Battlecard; Competitor | K21: Positioning notes | M21: Competitor identified | N21: Battlecard; Marketing review (Legal) | O21: Competitive win rate | P21: sales:selling-step | Q21: https://www.insperity.com/taxonomy/domain-sales/competitive-positioning | R21: domain-commercial-operations/competitor; core-measure/performance | S21: positioning (Marketing primitive; move to container) | T21: Proposed | U21: =COUNTIF(Services!$I$2:$I$200,"*"&A21&"*") -> 2
A22: SP-41 | B22: 2 | C22: Quote request | D22: SP-40 | E22: Propose | F22: Selling step | G22: A selling step that sends the census and opportunity to underwriting and receives a quote. | H22: Sales representative | I22: Automated | J22: Census; Opportunity | K22: Quote | M22: Census validated | N22: Underwriting guideline | O22: Quote turnaround time | P22: sales:selling-step | Q22: https://www.insperity.com/taxonomy/domain-sales/quote-request | R22: quote (move to container); core-issue/request | S22: quote (move to container) | T22: Proposed | U22: =COUNTIF(Services!$I$2:$I$200,"*"&A22&"*") -> 2
A23: SP-42 | B23: 2 | C23: Proposal preparation | D23: SP-40 | E23: Propose | F23: Selling step | G23: A selling step that assembles the quote, the co-employment split and the cost comparison into a proposal. | H23: Sales representative | I23: Hybrid | J23: Quote; Cost comparison; Benefits comparison; Liability inventory | K23: Proposal | L23: JS-CA-04; JS-CA-12 | M23: Quote received | N23: Proposal template; Allocation of employer responsibilities | O23: Proposals issued | P23: sales:selling-step | Q23: https://www.insperity.com/taxonomy/domain-sales/proposal-preparation | R23: domain-commercial-operations/proposal; core-process/drafting | T23: Proposed | U23: =COUNTIF(Services!$I$2:$I$200,"*"&A23&"*") -> 3
A24: SP-43 | B24: 2 | C24: Proposal presentation | D24: SP-40 | E24: Propose | F24: Selling step | G24: A selling step that presents the proposal to the buyer and walks through which employer responsibilities move, stay or are shared. | H24: Sales representative | I24: Manual | J24: Proposal | K24: Buyer feedback | L24: JS-CA-04; JS-CA-12 | M24: Proposal issued | N24: Disclosure requirement | O24: Proposal-to-decision rate | P24: sales:selling-step | Q24: https://www.insperity.com/taxonomy/domain-sales/proposal-presentation | R24: domain-commercial-operations/proposal; core-event/interaction | S24: presentation | T24: Proposed | U24: =COUNTIF(Services!$I$2:$I$200,"*"&A24&"*") -> 3
A25: SP-44 | B25: 2 | C25: Policy and records mapping | D25: SP-40 | E25: Propose | F25: Selling step | G25: A selling step that maps the prospect's handbook, policies and human resources records to the organization's policies and to what must move. | H25: Sales representative | I25: Hybrid | J25: Prospect handbook; Records inventory | K25: Policy map; Records transfer plan | L25: JS-HR-04; JS-HR-11 | M25: Proposal presented | N25: Workforce policy; Records retention policy | O25: Mappings completed | P25: sales:selling-step | Q25: https://www.insperity.com/taxonomy/domain-sales/policy-and-records-mapping | R25: core-policy/policy; core-asset/record; core-asset/mapping | T25: Proposed | U25: =COUNTIF(Services!$I$2:$I$200,"*"&A25&"*") -> 1
A26: SP-51 | B26: 2 | C26: Objection handling | D26: SP-50 | E26: Decide | F26: Selling step | G26: A selling step that answers the buyer's objections so the decision can proceed. | H26: Sales representative | I26: Manual | J26: Buyer feedback; Battlecard | K26: Objection log | M26: Objection raised | N26: Battlecard; Marketing review (Legal) | O26: Objections resolved | P26: sales:selling-step | Q26: https://www.insperity.com/taxonomy/domain-sales/objection-handling | R26: domain-sales/objection; core-process/action | T26: In model | U26: =COUNTIF(Services!$I$2:$I$200,"*"&A26&"*") -> 3
A27: SP-52 | B27: 2 | C27: Business case for decision makers | D27: SP-50 | E27: Decide | F27: Selling step | G27: A selling step that gives the owners and finance leaders the evidence they need to approve: cost, risk removed and value delivered. | H27: Sales representative | I27: Hybrid | J27: Cost comparison; Liability inventory; Proposal | K27: Business case | L27: JS-CA-05; JS-HR-05 | M27: Decision meeting scheduled | O27: Decisions reached | P27: sales:selling-step | Q27: https://www.insperity.com/taxonomy/domain-sales/business-case-for-decision-makers | R27: core-value/value; core-governance/assessment | S27: case | T27: Proposed | U27: =COUNTIF(Services!$I$2:$I$200,"*"&A27&"*") -> 1
A28: SP-53 | B28: 2 | C28: Negotiation | D28: SP-50 | E28: Decide | F28: Selling step | G28: A selling step in which the parties negotiate prices and terms. | H28: Sales representative | I28: Manual | J28: Proposal; Buyer feedback | K28: Agreed terms | M28: Buyer requests changes | N28: Pricing model; Pricing exception rules | O28: Discount given; Negotiation cycle length | P28: sales:selling-step | Q28: https://www.insperity.com/taxonomy/domain-commercial-operations/negotiation | R28: domain-commercial-operations/negotiation | T28: In model | U28: =COUNTIF(Services!$I$2:$I$200,"*"&A28&"*") -> 2
A29: SP-54 | B29: 2 | C29: Pricing exception request | D29: SP-50 | E29: Decide | F29: Selling step | G29: A selling step that asks pricing review to approve prices or terms outside the standard pricing model. | H29: Sales representative | I29: Hybrid | J29: Agreed terms; Quote | K29: Pricing exception decision | M29: Terms outside standard | N29: Pricing model; Pricing review | O29: Exceptions requested; Exception approval rate | P29: sales:selling-step | Q29: https://www.insperity.com/taxonomy/domain-sales/pricing-exception-request | R29: core-decision/pricing; core-issue/exception; core-issue/request | T29: Proposed | U29: =COUNTIF(Services!$I$2:$I$200,"*"&A29&"*") -> 1
A30: SP-55 | B30: 2 | C30: Transition communication planning | D30: SP-50 | E30: Decide | F30: Selling step | G30: A selling step that plans, with the buyer, how employees will be told what changes, when and whom to ask. | H30: Sales representative | I30: Manual | J30: Proposal; Policy map | K30: Employee communication plan | L30: JS-HR-07 | M30: Verbal decision | N30: Disclosure requirement | O30: Plans agreed | P30: sales:selling-step | Q30: https://www.insperity.com/taxonomy/domain-sales/transition-communication-planning | R30: core-services/communication; core-process/planning | T30: Proposed | U30: =COUNTIF(Services!$I$2:$I$200,"*"&A30&"*") -> 1
A31: SP-56 | B31: 2 | C31: Agreement signature | D31: SP-50 | E31: Decide | F31: Selling step | G31: A selling step in which the client signs the client service agreement, ending the opportunity in a win. | H31: Sales representative | I31: Automated | J31: Agreed terms; Client service agreement | K31: Executed client service agreement; Won opportunity; Sale | L31: JS-CA-05 | M31: Contract approved | N31: Client service agreement; Professional employer organization law | O31: Agreements signed; Win rate | P31: sales:selling-step | Q31: https://www.insperity.com/taxonomy/domain-sales/agreement-signature | R31: core-policy/agreement; signature (move to container) | S31: signature (move to container) | T31: Proposed | U31: =COUNTIF(Services!$I$2:$I$200,"*"&A31&"*") -> 5
A32: SP-57 | B32: 2 | C32: Win-loss capture | D32: SP-50 | E32: Decide | F32: Selling step | G32: A selling step that records why the opportunity was won or lost, and to whom, for win-loss analysis. | H32: Sales representative | I32: Hybrid | J32: Opportunity | K32: Won opportunity or Lost opportunity; Win-loss reason | M32: Opportunity closed | O32: Reasons captured | P32: sales:selling-step | Q32: https://www.insperity.com/taxonomy/domain-sales/win-loss-capture | R32: domain-commercial-operations/win; core-value/loss; core-asset/record | S32: reason | T32: Proposed | U32: =COUNTIF(Services!$I$2:$I$200,"*"&A32&"*") -> 2
A33: SP-61 | B33: 2 | C33: Booking entry | D33: SP-60 | E33: Onboard | F33: Selling step | G33: A selling step that records the sale as a booking before the client's service starts. | H33: Sales representative | I33: Automated | J33: Executed client service agreement | K33: Booking | M33: Agreement executed | N33: Booking rules; Sales incentive plan | O33: Bookings; Worksite employees sold | P33: sales:selling-step | Q33: https://www.insperity.com/taxonomy/domain-sales/booking-entry | R33: domain-sales/booking | T33: Proposed | U33: =COUNTIF(Services!$I$2:$I$200,"*"&A33&"*") -> 3
A34: SP-62 | B34: 2 | C34: Client handoff | D34: SP-60 | E34: Onboard | F34: Selling step | G34: A selling step that passes the won client, with its census, liability inventory, policy map and communication plan, to the team that brings it into service. | H34: Sales representative | I34: Hybrid | J34: Booking; Census; Liability inventory; Policy map; Employee communication plan | K34: Handoff package | M34: Booking entered | N34: Handoff checklist | O34: Handoff completeness; Time to handoff | P34: sales:selling-step | Q34: https://www.insperity.com/taxonomy/domain-sales/client-handoff | R34: core-role/client; core-event/handoff | T34: In model | U34: =COUNTIF(Services!$I$2:$I$200,"*"&A34&"*") -> 2

Sheet Services
A1: ID | B1: Service | C1: Category | D1: Definition | E1: Service consumer | F1: Provider domain | G1: Delivery mode | H1: Performed by | I1: Supports process steps | J1: Capability exercised | K1: Inputs | L1: Outputs | M1: Service measures | N1: Governed by | O1: Shared interface (Commercial Operations) | P1: Core taxonomy match (skos:broadMatch) | Q1: Proposed taxonomy IRI | R1: Status | S1: Steps supported (calculated)
A2: SV-01 | B2: Discovery consultation | C2: Buyer-facing service | D2: A service in which the organization helps a prospect understand its human resources situation, risks and the jobs it is trying to get done. | E2: Buyer (Client Admin, HR Specialist) | F2: Sales | G2: Manual | H2: Sales representative | I2: SP-14;SP-15;SP-22 | J2: Customer relationship management | K2: Discovery guide | L2: Discovery notes; Job study | M2: Meetings held | N2: Discovery guide | P2: https://www.insperity.com/taxonomy/core-services/sales-services | Q2: https://www.insperity.com/taxonomy/domain-sales/discovery-consultation | R2: Proposed | S2: =IF(LEN(TRIM(I2))=0,0,LEN(I2)-LEN(SUBSTITUTE(I2,";",""))+1) -> 3
A3: SV-02 | B3: Total cost of employment analysis | C3: Buyer-facing service | D3: A service that compares the prospect's all-in cost per employee today with the cost under the organization's offering. | E3: Buyer (Client Admin) | F3: Sales | G3: Hybrid | H3: Sales representative; Sales advisor agent | I3: SP-33;SP-52 | J3: Business intelligence | K3: Census; Current costs; Pricing model | L3: Cost comparison | M3: Comparisons delivered | N3: Pricing model | P3: https://www.insperity.com/taxonomy/core-services/sales-services | Q3: https://www.insperity.com/taxonomy/domain-sales/total-cost-of-employment-analysis | R3: Proposed | S3: =IF(LEN(TRIM(I3))=0,0,LEN(I3)-LEN(SUBSTITUTE(I3,";",""))+1) -> 2
A4: SV-03 | B4: Product demonstration | C4: Buyer-facing service | D4: A service that shows the buyer the services and technology in use. | E4: Buyer (Client Admin, HR Specialist) | F4: Sales | G4: Manual | H4: Sales representative | I4: SP-31 | J4: Customer relationship management | K4: Demonstration environment | L4: Demonstration feedback | M4: Demonstrations held | N4: Demonstration script | P4: https://www.insperity.com/taxonomy/core-services/sales-services | Q4: https://www.insperity.com/taxonomy/domain-sales/product-demonstration | R4: Proposed | S4: =IF(LEN(TRIM(I4))=0,0,LEN(I4)-LEN(SUBSTITUTE(I4,";",""))+1) -> 1
A5: SV-04 | B5: Benefits comparison | C5: Buyer-facing service | D5: A service that compares the benefit plans employees have today with those they would see. | E5: Buyer (HR Specialist) | F5: Sales | G5: Hybrid | H5: Sales representative | I5: SP-34 | J5: Product information management | K5: Census; Benefit plan catalog | L5: Benefits comparison | M5: Comparisons delivered | N5: Employee benefits law | P5: https://www.insperity.com/taxonomy/core-services/sales-services | Q5: https://www.insperity.com/taxonomy/domain-sales/benefits-comparison | R5: Proposed | S5: =IF(LEN(TRIM(I5))=0,0,LEN(I5)-LEN(SUBSTITUTE(I5,";",""))+1) -> 1
A6: SV-05 | B6: Proposal service | C6: Buyer-facing service | D6: A service that prepares and presents a proposal of offerings, terms, prices and the co-employment split. | E6: Buyer (Client Admin) | F6: Sales | G6: Hybrid | H6: Sales representative; Sales advisor agent | I6: SP-42;SP-43 | J6: Customer relationship management | K6: Quote; Cost comparison; Liability inventory | L6: Proposal | M6: Proposals issued; Proposal turnaround time | N6: Proposal template | O6: commercialops:proposal | P6: https://www.insperity.com/taxonomy/core-services/sales-services | Q6: https://www.insperity.com/taxonomy/domain-sales/proposal-service | R6: Proposed | S6: =IF(LEN(TRIM(I6))=0,0,LEN(I6)-LEN(SUBSTITUTE(I6,";",""))+1) -> 2
A7: SV-06 | B7: Transition planning | C7: Buyer-facing service | D7: A service that maps the buyer's policies and records and plans employee communications for the move. | E7: Buyer (HR Specialist) | F7: Sales | G7: Manual | H7: Sales representative | I7: SP-44;SP-55 | K7: Prospect handbook; Records inventory | L7: Policy map; Records transfer plan; Employee communication plan | M7: Plans agreed | N7: Workforce policy; Disclosure requirement | P7: https://www.insperity.com/taxonomy/core-services/sales-services | Q7: https://www.insperity.com/taxonomy/domain-sales/transition-planning | R7: Proposed | S7: =IF(LEN(TRIM(I7))=0,0,LEN(I7)-LEN(SUBSTITUTE(I7,";",""))+1) -> 2
A8: SV-10 | B8: Lead routing and assignment | C8: Sales operations service | D8: A service that assigns each accepted lead to the representative responsible for its territory or segment. | E8: Sales representative | F8: Sales operations | G8: Automated | H8: Workflow automation | I8: SP-12;SP-13 | J8: Customer relationship management | K8: Lead; Territory | L8: Assigned lead | M8: Speed to lead | N8: Territory plan | P8: https://www.insperity.com/taxonomy/core-services/sales-operations | Q8: https://www.insperity.com/taxonomy/domain-sales/lead-routing-and-assignment | R8: Proposed | S8: =IF(LEN(TRIM(I8))=0,0,LEN(I8)-LEN(SUBSTITUTE(I8,";",""))+1) -> 2
A9: SV-11 | B9: Lead and opportunity scoring | C9: Sales operations service | D9: A service that scores leads and opportunities by fit and likelihood to close. | E9: Sales representative; Sales manager | F9: Sales operations | G9: Automated | H9: Scoring model | I9: SP-13;SP-21 | J9: Artificial intelligence and machine learning | K9: Lead; Firmographic profile; Intent signal; Engagement signal | L9: Lead score; Opportunity score | M9: Score accuracy | N9: Scoring model; AI circuit breaker | P9: https://www.insperity.com/taxonomy/core-services/sales-operations | Q9: https://www.insperity.com/taxonomy/domain-sales/lead-and-opportunity-scoring | R9: Proposed | S9: =IF(LEN(TRIM(I9))=0,0,LEN(I9)-LEN(SUBSTITUTE(I9,";",""))+1) -> 2
A10: SV-12 | B10: Pipeline management | C10: Sales operations service | D10: A service that keeps each opportunity's stage, value and next step current and reviews the pipeline. | E10: Sales manager | F10: Sales operations | G10: Hybrid | H10: Sales manager; Customer relationship management system | I10: SP-21;SP-23;SP-31;SP-41;SP-42;SP-53;SP-56 | J10: Customer relationship management | K10: Opportunity | L10: Pipeline | M10: Pipeline coverage; Time in stage | N10: Sales plan | O10: commercialops:opportunity | P10: https://www.insperity.com/taxonomy/core-services/sales-operations | Q10: https://www.insperity.com/taxonomy/domain-sales/pipeline-management | R10: Proposed | S10: =IF(LEN(TRIM(I10))=0,0,LEN(I10)-LEN(SUBSTITUTE(I10,";",""))+1) -> 7
A11: SV-13 | B11: Sales forecasting | C11: Sales operations service | D11: A service that estimates the sales expected to close in each period. | E11: Sales executive | F11: Sales operations | G11: Hybrid | H11: Sales manager; Forecast model | I11: SP-23;SP-56 | J11: Business intelligence | K11: Pipeline; Win rate | L11: Sales forecast | M11: Forecast accuracy | N11: Sales plan | P11: https://www.insperity.com/taxonomy/core-services/sales-operations | Q11: https://www.insperity.com/taxonomy/domain-sales/sales-forecasting | R11: Proposed | S11: =IF(LEN(TRIM(I11))=0,0,LEN(I11)-LEN(SUBSTITUTE(I11,";",""))+1) -> 2
A12: SV-14 | B12: Territory and quota planning | C12: Sales operations service | D12: A service that assigns territories and sets quotas for each period. | E12: Sales manager; Sales representative | F12: Sales operations | G12: Hybrid | H12: Sales operations analyst | I12: SP-11 | J12: Business intelligence | K12: Market structure; Prior bookings | L12: Territory plan; Quota | M12: Quota attainment spread | N12: Sales plan | P12: https://www.insperity.com/taxonomy/core-services/sales-operations | Q12: https://www.insperity.com/taxonomy/domain-sales/territory-and-quota-planning | R12: Proposed | S12: =IF(LEN(TRIM(I12))=0,0,LEN(I12)-LEN(SUBSTITUTE(I12,";",""))+1) -> 1
A13: SV-15 | B13: Sales incentive and commission calculation | C13: Sales operations service | D13: A service that calculates the incentives and commissions earned on bookings. | E13: Sales representative | F13: Sales operations | G13: Automated | H13: Incentive compensation system | I13: SP-61 | J13: Billing and accounting management | K13: Booking; Sales incentive plan | L13: Commission statement | M13: Statement accuracy; Disputes raised | N13: Sales incentive plan | P13: https://www.insperity.com/taxonomy/core-services/sales-operations | Q13: https://www.insperity.com/taxonomy/domain-sales/sales-incentive-and-commission-calculation | R13: Proposed | S13: =IF(LEN(TRIM(I13))=0,0,LEN(I13)-LEN(SUBSTITUTE(I13,";",""))+1) -> 1
A14: SV-16 | B14: Booking and order entry | C14: Sales operations service | D14: A service that records the booking and opens the order for implementation. | E14: Sales representative; Client success manager | F14: Sales operations | G14: Automated | H14: Customer relationship management system | I14: SP-61;SP-62 | J14: Order management | K14: Executed client service agreement | L14: Booking; Order | M14: Booking accuracy | N14: Booking rules | O14: commercialops:client-service-agreement | P14: https://www.insperity.com/taxonomy/core-services/order-entry | Q14: https://www.insperity.com/taxonomy/domain-sales/booking-and-order-entry | R14: Proposed | S14: =IF(LEN(TRIM(I14))=0,0,LEN(I14)-LEN(SUBSTITUTE(I14,";",""))+1) -> 2
A15: SV-17 | B15: Sales engagement automation | C15: Sales operations service | D15: A service that runs outreach cadences and logs each contact. | E15: Sales representative | F15: Sales operations | G15: Automated | H15: Sales engagement system | I15: SP-11;SP-12 | J15: Customer relationship management | K15: Lead; Cadence | L15: Interaction log | M15: Response rate | N15: Cadence; Consent requirement | P15: https://www.insperity.com/taxonomy/core-services/sales-operations | Q15: https://www.insperity.com/taxonomy/domain-sales/sales-engagement-automation | R15: Proposed | S15: =IF(LEN(TRIM(I15))=0,0,LEN(I15)-LEN(SUBSTITUTE(I15,";",""))+1) -> 2
A16: SV-18 | B16: Customer relationship management data stewardship | C16: Sales operations service | D16: A service that keeps account, lead and opportunity records complete, current and free of duplicates. | E16: Sales manager; Sales operations analyst | F16: Sales operations | G16: Hybrid | H16: Data steward | I16: SP-13;SP-23;SP-56;SP-57;SP-61 | J16: Master data management | K16: Account; Lead; Opportunity | L16: Corrected records | M16: Completeness; Uniqueness; Timeliness | N16: Data quality rules | O16: commercialops:account | P16: https://www.insperity.com/taxonomy/core-services/data-stewardship | Q16: https://www.insperity.com/taxonomy/domain-sales/customer-relationship-management-data-stewardship | R16: Proposed | S16: =IF(LEN(TRIM(I16))=0,0,LEN(I16)-LEN(SUBSTITUTE(I16,";",""))+1) -> 5
A17: SV-20 | B17: Sales enablement and training | C17: Enablement service | D17: A service that equips representatives with the knowledge, content and tools to sell. | E17: Sales representative | F17: Sales | G17: Manual | H17: Sales enablement manager | I17: SP-14;SP-31;SP-35;SP-43;SP-51 | K17: Playbooks; Content; Battlecards | L17: Certified representatives | M17: Time to first booking | N17: Sales plan | P17: https://www.insperity.com/taxonomy/core-services/sales-services | Q17: https://www.insperity.com/taxonomy/domain-sales/sales-enablement-and-training | R17: Proposed | S17: =IF(LEN(TRIM(I17))=0,0,LEN(I17)-LEN(SUBSTITUTE(I17,";",""))+1) -> 5
A18: SV-21 | B18: Sales advisor agent | C18: Enablement service | D18: An automated service, delivered by a digital agent, that advises representatives at each selling step on the next best action, answers and content. | E18: Sales representative | F18: Sales | G18: Automated | H18: Artificial intelligence agent (PEO Sales Advisor) | I18: SP-14;SP-15;SP-21;SP-33;SP-42;SP-51 | J18: Artificial intelligence and machine learning | K18: Opportunity; Job study; Battlecard; Pricing model | L18: Recommendations; Draft content | M18: Recommendation acceptance; Mean time between hallucinations | N18: AI circuit breaker; Responsible artificial intelligence policy | P18: https://www.insperity.com/taxonomy/core-services/sales-services | Q18: https://www.insperity.com/taxonomy/domain-sales/sales-advisor-agent | R18: Proposed | S18: =IF(LEN(TRIM(I18))=0,0,LEN(I18)-LEN(SUBSTITUTE(I18,";",""))+1) -> 6
A19: SV-30 | B19: Marketing lead handoff | C19: Shared commercial service | D19: A service, provided by Marketing, that passes marketing-qualified leads to sales. | E19: Sales representative | F19: Marketing | G19: Automated | H19: Marketing automation | I19: SP-13 | J19: Customer relationship management | K19: Marketing-qualified lead | L19: Lead | M19: Lead acceptance rate | N19: Lead service level agreement | O19: commercialops:lead | P19: https://www.insperity.com/taxonomy/core-services/marketing-management | Q19: https://www.insperity.com/taxonomy/domain-marketing/marketing-lead-handoff | R19: Proposed | S19: =IF(LEN(TRIM(I19))=0,0,LEN(I19)-LEN(SUBSTITUTE(I19,";",""))+1) -> 1
A20: SV-31 | B20: Competitive intelligence | C20: Shared commercial service | D20: A service, provided by Marketing, that supplies battlecards and competitor profiles. | E20: Sales representative | F20: Marketing | G20: Hybrid | H20: Competitive intelligence analyst | I20: SP-35;SP-51;SP-57 | J20: Business intelligence | K20: Win-loss reasons; Market research | L20: Battlecard; Competitor profile | M20: Battlecard usage; Competitive win rate | N20: Marketing review (Legal) | O20: commercialops:competitor | P20: https://www.insperity.com/taxonomy/core-services/competitive-analysis | Q20: https://www.insperity.com/taxonomy/domain-marketing/competitive-intelligence | R20: Proposed | S20: =IF(LEN(TRIM(I20))=0,0,LEN(I20)-LEN(SUBSTITUTE(I20,";",""))+1) -> 3
A21: SV-32 | B21: Census intake | C21: Shared commercial service | D21: A service, provided by Pricing and contracts, that receives, validates and protects the census. | E21: Sales representative | F21: Pricing and contracts | G21: Hybrid | H21: Underwriting analyst | I21: SP-32 | J21: Data privacy | K21: Census | L21: Validated census | M21: Census completeness; Census turnaround time | N21: Data protection norms (Legal) | O21: census (move to container) | P21: https://www.insperity.com/taxonomy/core-services/sales-operations | Q21: https://www.insperity.com/taxonomy/domain-pricing-and-contracts/census-intake | R21: Proposed | S21: =IF(LEN(TRIM(I21))=0,0,LEN(I21)-LEN(SUBSTITUTE(I21,";",""))+1) -> 1
A22: SV-33 | B22: Underwriting and quoting | C22: Shared commercial service | D22: A service, provided by Pricing and contracts, that underwrites the prospect and returns a quote. | E22: Sales representative | F22: Pricing and contracts | G22: Hybrid | H22: Underwriter | I22: SP-41 | J22: Risk management | K22: Validated census; Loss run; Class codes | L22: Quote; Underwriting decision | M22: Quote turnaround time | N22: Underwriting guideline | O22: quote (move to container) | P22: https://www.insperity.com/taxonomy/core-services/pricing-management | Q22: https://www.insperity.com/taxonomy/domain-pricing-and-contracts/underwriting-and-quoting | R22: Proposed | S22: =IF(LEN(TRIM(I22))=0,0,LEN(I22)-LEN(SUBSTITUTE(I22,";",""))+1) -> 1
A23: SV-34 | B23: Pricing review | C23: Shared commercial service | D23: A service, provided by Pricing and contracts, that reviews and approves non-standard prices or terms. | E23: Sales representative | F23: Pricing and contracts | G23: Manual | H23: Pricing review board | I23: SP-54 | J23: Risk management | K23: Pricing exception request | L23: Pricing exception decision | M23: Exception turnaround time | N23: Pricing model | O23: commercialops:proposal | P23: https://www.insperity.com/taxonomy/core-services/pricing-management | Q23: https://www.insperity.com/taxonomy/domain-pricing-and-contracts/pricing-review | R23: Proposed | S23: =IF(LEN(TRIM(I23))=0,0,LEN(I23)-LEN(SUBSTITUTE(I23,";",""))+1) -> 1
A24: SV-35 | B24: Contract generation and signature | C24: Shared commercial service | D24: A service, provided by Pricing and contracts, that drafts the client service agreement and collects signatures. | E24: Sales representative; Buyer | F24: Pricing and contracts | G24: Automated | H24: Contract management system | I24: SP-56 | J24: Order management | K24: Agreed terms | L24: Executed client service agreement | M24: Time to signature | N24: Client service agreement template | O24: commercialops:client-service-agreement | P24: https://www.insperity.com/taxonomy/core-services/contract-management | Q24: https://www.insperity.com/taxonomy/domain-pricing-and-contracts/contract-generation-and-signature | R24: Proposed | S24: =IF(LEN(TRIM(I24))=0,0,LEN(I24)-LEN(SUBSTITUTE(I24,";",""))+1) -> 1
A25: SV-36 | B25: Contract and disclosure review | C25: Shared commercial service | D25: A service, provided by Legal, that reviews non-standard agreements and the disclosures given to the buyer. | E25: Sales representative | F25: Legal | G25: Manual | H25: Counsel | I25: SP-43;SP-53;SP-56 | K25: Agreed terms; Proposal | L25: Review decision | M25: Review turnaround time | N25: Professional employer organization law; Disclosure requirement | O25: commercialops:clause | P25: https://www.insperity.com/taxonomy/core-services/governance-services | Q25: https://www.insperity.com/taxonomy/domain-legal/contract-and-disclosure-review | R25: Proposed | S25: =IF(LEN(TRIM(I25))=0,0,LEN(I25)-LEN(SUBSTITUTE(I25,";",""))+1) -> 3
A26: SV-37 | B26: Partner opportunity registration | C26: Shared commercial service | D26: A service, provided by Partner and channel, that registers partner-sourced opportunities and credits the partner. | E26: Sales representative; Channel partner | F26: Partner and channel | G26: Automated | H26: Partner portal | I26: SP-23 | J26: Customer relationship management | K26: Partner-sourced opportunity | L26: Opportunity; Attribution | M26: Registration turnaround time | N26: Partner program | O26: commercialops:opportunity | P26: https://www.insperity.com/taxonomy/core-services/sales-operations | Q26: https://www.insperity.com/taxonomy/domain-partner-and-channel/partner-opportunity-registration | R26: Proposed | S26: =IF(LEN(TRIM(I26))=0,0,LEN(I26)-LEN(SUBSTITUTE(I26,";",""))+1) -> 1
A27: SV-38 | B27: Client implementation intake | C27: Shared commercial service | D27: A service, provided by Customer success, that receives the handoff package and starts client onboarding. | E27: Sales representative | F27: Customer success | G27: Hybrid | H27: Client success manager | I27: SP-62 | J27: Customer relationship management | K27: Handoff package | L27: Onboarding plan | M27: Handoff completeness; Time to first payroll | N27: Onboarding playbook | O27: commercialops:account | P27: https://www.insperity.com/taxonomy/core-services/onboarding-management | Q27: https://www.insperity.com/taxonomy/domain-customer-success/client-implementation-intake | R27: Proposed | S27: =IF(LEN(TRIM(I27))=0,0,LEN(I27)-LEN(SUBSTITUTE(I27,";",""))+1) -> 1

Sheet Process × Service
A1: Step | B1: Selling step | C1: SV-01 | D1: SV-02 | E1: SV-03 | F1: SV-04 | G1: SV-05 | H1: SV-06 | I1: SV-10 | J1: SV-11 | K1: SV-12 | L1: SV-13 | M1: SV-14 | N1: SV-15 | O1: SV-16 | P1: SV-17 | Q1: SV-18 | R1: SV-20 | S1: SV-21 | T1: SV-30 | U1: SV-31 | V1: SV-32 | W1: SV-33 | X1: SV-34 | Y1: SV-35 | Z1: SV-36 | AA1: SV-37 | AB1: SV-38 | AC1: Services
B2: Calculated from Services › Supports process steps. Edit that column, not this grid. | C2: Discovery consultation | D2: Total cost of employment analysis | E2: Product demonstration | F2: Benefits comparison | G2: Proposal service | H2: Transition planning | I2: Lead routing and assignment | J2: Lead and opportunity scoring | K2: Pipeline management | L2: Sales forecasting | M2: Territory and quota planning | N2: Sales incentive and commission calculation | O2: Booking and order entry | P2: Sales engagement automation | Q2: Customer relationship management data stewardship | R2: Sales enablement and training | S2: Sales advisor agent | T2: Marketing lead handoff | U2: Competitive intelligence | V2: Census intake | W2: Underwriting and quoting | X2: Pricing review | Y2: Contract generation and signature | Z2: Contract and disclosure review | AA2: Partner opportunity registration | AB2: Client implementation intake
A3: SP-11 | B3: Prospecting (Discover) | C3: =IF(ISNUMBER(SEARCH(";"&$A3&";",";"&SUBSTITUTE(INDEX(Services!$I$2:$I$27,MATCH(C$1,Services!$A$2:$A$27,0))," ","")&";")),"●","") | D3: =IF(ISNUMBER(SEARCH(";"&$A3&";",";"&SUBSTITUTE(INDEX(Services!$I$2:$I$27,MATCH(D$1,Services!$A$2:$A$27,0))," ","")&";")),"●","") | E3: =IF(ISNUMBER(SEARCH(";"&$A3&";",";"&SUBSTITUTE(INDEX(Services!$I$2:$I$27,MATCH(E$1,Services!$A$2:$A$27,0))," ","")&";")),"●","") | F3: =IF(ISNUMBER(SEARCH(";"&$A3&";",";"&SUBSTITUTE(INDEX(Services!$I$2:$I$27,MATCH(F$1,Services!$A$2:$A$27,0))," ","")&";")),"●","") | G3: =IF(ISNUMBER(SEARCH(";"&$A3&";",";"&SUBSTITUTE(INDEX(Services!$I$2:$I$27,MATCH(G$1,Services!$A$2:$A$27,0))," ","")&";")),"●","") | H3: =IF(ISNUMBER(SEARCH(";"&$A3&";",";"&SUBSTITUTE(INDEX(Services!$I$2:$I$27,MATCH(H$1,Services!$A$2:$A$27,0))," ","")&";")),"●","") | I3: =IF(ISNUMBER(SEARCH(";"&$A3&";",";"&SUBSTITUTE(INDEX(Services!$I$2:$I$27,MATCH(I$1,Services!$A$2:$A$27,0))," ","")&";")),"●","") | J3: =IF(ISNUMBER(SEARCH(";"&$A3&";",";"&SUBSTITUTE(INDEX(Services!$I$2:$I$27,MATCH(J$1,Services!$A$2:$A$27,0))," ","")&";")),"●","") | ... AB3: =IF(ISNUMBER(SEARCH(";"&$A3&";",";"&SUBSTITUTE(INDEX(Services!$I$2:$I$27,MATCH(AB$1,Services!$A$2:$A$27,0))," ","")&";")),"●","") | AC3: =COUNTIF(C3:AB3,"●") -> 2
A4: SP-12 | B4: Outreach (Discover) | C4: =IF(ISNUMBER(SEARCH(";"&$A4&";",";"&SUBSTITUTE(INDEX(Services!$I$2:$I$27,MATCH(C$1,Services!$A$2:$A$27,0))," ","")&";")),"●","") | D4: =IF(ISNUMBER(SEARCH(";"&$A4&";",";"&SUBSTITUTE(INDEX(Services!$I$2:$I$27,MATCH(D$1,Services!$A$2:$A$27,0))," ","")&";")),"●","") | E4: =IF(ISNUMBER(SEARCH(";"&$A4&";",";"&SUBSTITUTE(INDEX(Services!$I$2:$I$27,MATCH(E$1,Services!$A$2:$A$27,0))," ","")&";")),"●","") | F4: =IF(ISNUMBER(SEARCH(";"&$A4&";",";"&SUBSTITUTE(INDEX(Services!$I$2:$I$27,MATCH(F$1,Services!$A$2:$A$27,0))," ","")&";")),"●","") | G4: =IF(ISNUMBER(SEARCH(";"&$A4&";",";"&SUBSTITUTE(INDEX(Services!$I$2:$I$27,MATCH(G$1,Services!$A$2:$A$27,0))," ","")&";")),"●","") | H4: =IF(ISNUMBER(SEARCH(";"&$A4&";",";"&SUBSTITUTE(INDEX(Services!$I$2:$I$27,MATCH(H$1,Services!$A$2:$A$27,0))," ","")&";")),"●","") | I4: =IF(ISNUMBER(SEARCH(";"&$A4&";",";"&SUBSTITUTE(INDEX(Services!$I$2:$I$27,MATCH(I$1,Services!$A$2:$A$27,0))," ","")&";")),"●","") -> ● | J4: =IF(ISNUMBER(SEARCH(";"&$A4&";",";"&SUBSTITUTE(INDEX(Services!$I$2:$I$27,MATCH(J$1,Services!$A$2:$A$27,0))," ","")&";")),"●","") | ... AB4: =IF(ISNUMBER(SEARCH(";"&$A4&";",";"&SUBSTITUTE(INDEX(Services!$I$2:$I$27,MATCH(AB$1,Services!$A$2:$A$27,0))," ","")&";")),"●","") | AC4: =COUNTIF(C4:AB4,"●") -> 2
A5: SP-13 | B5: Lead acceptance (Discover) | C5: =IF(ISNUMBER(SEARCH(";"&$A5&";",";"&SUBSTITUTE(INDEX(Services!$I$2:$I$27,MATCH(C$1,Services!$A$2:$A$27,0))," ","")&";")),"●","") | D5: =IF(ISNUMBER(SEARCH(";"&$A5&";",";"&SUBSTITUTE(INDEX(Services!$I$2:$I$27,MATCH(D$1,Services!$A$2:$A$27,0))," ","")&";")),"●","") | E5: =IF(ISNUMBER(SEARCH(";"&$A5&";",";"&SUBSTITUTE(INDEX(Services!$I$2:$I$27,MATCH(E$1,Services!$A$2:$A$27,0))," ","")&";")),"●","") | F5: =IF(ISNUMBER(SEARCH(";"&$A5&";",";"&SUBSTITUTE(INDEX(Services!$I$2:$I$27,MATCH(F$1,Services!$A$2:$A$27,0))," ","")&";")),"●","") | G5: =IF(ISNUMBER(SEARCH(";"&$A5&";",";"&SUBSTITUTE(INDEX(Services!$I$2:$I$27,MATCH(G$1,Services!$A$2:$A$27,0))," ","")&";")),"●","") | H5: =IF(ISNUMBER(SEARCH(";"&$A5&";",";"&SUBSTITUTE(INDEX(Services!$I$2:$I$27,MATCH(H$1,Services!$A$2:$A$27,0))," ","")&";")),"●","") | I5: =IF(ISNUMBER(SEARCH(";"&$A5&";",";"&SUBSTITUTE(INDEX(Services!$I$2:$I$27,MATCH(I$1,Services!$A$2:$A$27,0))," ","")&";")),"●","") -> ● | J5: =IF(ISNUMBER(SEARCH(";"&$A5&";",";"&SUBSTITUTE(INDEX(Services!$I$2:$I$27,MATCH(J$1,Services!$A$2:$A$27,0))," ","")&";")),"●","") -> ● | ... AB5: =IF(ISNUMBER(SEARCH(";"&$A5&";",";"&SUBSTITUTE(INDEX(Services!$I$2:$I$27,MATCH(AB$1,Services!$A$2:$A$27,0))," ","")&";")),"●","") | AC5: =COUNTIF(C5:AB5,"●") -> 4
A6: SP-14 | B6: Discovery meeting (Discover) | C6: =IF(ISNUMBER(SEARCH(";"&$A6&";",";"&SUBSTITUTE(INDEX(Services!$I$2:$I$27,MATCH(C$1,Services!$A$2:$A$27,0))," ","")&";")),"●","") -> ● | D6: =IF(ISNUMBER(SEARCH(";"&$A6&";",";"&SUBSTITUTE(INDEX(Services!$I$2:$I$27,MATCH(D$1,Services!$A$2:$A$27,0))," ","")&";")),"●","") | E6: =IF(ISNUMBER(SEARCH(";"&$A6&";",";"&SUBSTITUTE(INDEX(Services!$I$2:$I$27,MATCH(E$1,Services!$A$2:$A$27,0))," ","")&";")),"●","") | F6: =IF(ISNUMBER(SEARCH(";"&$A6&";",";"&SUBSTITUTE(INDEX(Services!$I$2:$I$27,MATCH(F$1,Services!$A$2:$A$27,0))," ","")&";")),"●","") | G6: =IF(ISNUMBER(SEARCH(";"&$A6&";",";"&SUBSTITUTE(INDEX(Services!$I$2:$I$27,MATCH(G$1,Services!$A$2:$A$27,0))," ","")&";")),"●","") | H6: =IF(ISNUMBER(SEARCH(";"&$A6&";",";"&SUBSTITUTE(INDEX(Services!$I$2:$I$27,MATCH(H$1,Services!$A$2:$A$27,0))," ","")&";")),"●","") | I6: =IF(ISNUMBER(SEARCH(";"&$A6&";",";"&SUBSTITUTE(INDEX(Services!$I$2:$I$27,MATCH(I$1,Services!$A$2:$A$27,0))," ","")&";")),"●","") | J6: =IF(ISNUMBER(SEARCH(";"&$A6&";",";"&SUBSTITUTE(INDEX(Services!$I$2:$I$27,MATCH(J$1,Services!$A$2:$A$27,0))," ","")&";")),"●","") | ... AB6: =IF(ISNUMBER(SEARCH(";"&$A6&";",";"&SUBSTITUTE(INDEX(Services!$I$2:$I$27,MATCH(AB$1,Services!$A$2:$A$27,0))," ","")&";")),"●","") | AC6: =COUNTIF(C6:AB6,"●") -> 3
A7: SP-15 | B7: Jobs and needs capture (Discover) | C7: =IF(ISNUMBER(SEARCH(";"&$A7&";",";"&SUBSTITUTE(INDEX(Services!$I$2:$I$27,MATCH(C$1,Services!$A$2:$A$27,0))," ","")&";")),"●","") -> ● | D7: =IF(ISNUMBER(SEARCH(";"&$A7&";",";"&SUBSTITUTE(INDEX(Services!$I$2:$I$27,MATCH(D$1,Services!$A$2:$A$27,0))," ","")&";")),"●","") | E7: =IF(ISNUMBER(SEARCH(";"&$A7&";",";"&SUBSTITUTE(INDEX(Services!$I$2:$I$27,MATCH(E$1,Services!$A$2:$A$27,0))," ","")&";")),"●","") | F7: =IF(ISNUMBER(SEARCH(";"&$A7&";",";"&SUBSTITUTE(INDEX(Services!$I$2:$I$27,MATCH(F$1,Services!$A$2:$A$27,0))," ","")&";")),"●","") | G7: =IF(ISNUMBER(SEARCH(";"&$A7&";",";"&SUBSTITUTE(INDEX(Services!$I$2:$I$27,MATCH(G$1,Services!$A$2:$A$27,0))," ","")&";")),"●","") | H7: =IF(ISNUMBER(SEARCH(";"&$A7&";",";"&SUBSTITUTE(INDEX(Services!$I$2:$I$27,MATCH(H$1,Services!$A$2:$A$27,0))," ","")&";")),"●","") | I7: =IF(ISNUMBER(SEARCH(";"&$A7&";",";"&SUBSTITUTE(INDEX(Services!$I$2:$I$27,MATCH(I$1,Services!$A$2:$A$27,0))," ","")&";")),"●","") | J7: =IF(ISNUMBER(SEARCH(";"&$A7&";",";"&SUBSTITUTE(INDEX(Services!$I$2:$I$27,MATCH(J$1,Services!$A$2:$A$27,0))," ","")&";")),"●","") | ... AB7: =IF(ISNUMBER(SEARCH(";"&$A7&";",";"&SUBSTITUTE(INDEX(Services!$I$2:$I$27,MATCH(AB$1,Services!$A$2:$A$27,0))," ","")&";")),"●","") | AC7: =COUNTIF(C7:AB7,"●") -> 2
A8: SP-21 | B8: Opportunity qualification (Qualify) | C8: =IF(ISNUMBER(SEARCH(";"&$A8&";",";"&SUBSTITUTE(INDEX(Services!$I$2:$I$27,MATCH(C$1,Services!$A$2:$A$27,0))," ","")&";")),"●","") | D8: =IF(ISNUMBER(SEARCH(";"&$A8&";",";"&SUBSTITUTE(INDEX(Services!$I$2:$I$27,MATCH(D$1,Services!$A$2:$A$27,0))," ","")&";")),"●","") | E8: =IF(ISNUMBER(SEARCH(";"&$A8&";",";"&SUBSTITUTE(INDEX(Services!$I$2:$I$27,MATCH(E$1,Services!$A$2:$A$27,0))," ","")&";")),"●","") | F8: =IF(ISNUMBER(SEARCH(";"&$A8&";",";"&SUBSTITUTE(INDEX(Services!$I$2:$I$27,MATCH(F$1,Services!$A$2:$A$27,0))," ","")&";")),"●","") | G8: =IF(ISNUMBER(SEARCH(";"&$A8&";",";"&SUBSTITUTE(INDEX(Services!$I$2:$I$27,MATCH(G$1,Services!$A$2:$A$27,0))," ","")&";")),"●","") | H8: =IF(ISNUMBER(SEARCH(";"&$A8&";",";"&SUBSTITUTE(INDEX(Services!$I$2:$I$27,MATCH(H$1,Services!$A$2:$A$27,0))," ","")&";")),"●","") | I8: =IF(ISNUMBER(SEARCH(";"&$A8&";",";"&SUBSTITUTE(INDEX(Services!$I$2:$I$27,MATCH(I$1,Services!$A$2:$A$27,0))," ","")&";")),"●","") | J8: =IF(ISNUMBER(SEARCH(";"&$A8&";",";"&SUBSTITUTE(INDEX(Services!$I$2:$I$27,MATCH(J$1,Services!$A$2:$A$27,0))," ","")&";")),"●","") -> ● | ... AB8: =IF(ISNUMBER(SEARCH(";"&$A8&";",";"&SUBSTITUTE(INDEX(Services!$I$2:$I$27,MATCH(AB$1,Services!$A$2:$A$27,0))," ","")&";")),"●","") | AC8: =COUNTIF(C8:AB8,"●") -> 3
A9: SP-22 | B9: Employer liability review (Qualify) | C9: =IF(ISNUMBER(SEARCH(";"&$A9&";",";"&SUBSTITUTE(INDEX(Services!$I$2:$I$27,MATCH(C$1,Services!$A$2:$A$27,0))," ","")&";")),"●","") -> ● | D9: =IF(ISNUMBER(SEARCH(";"&$A9&";",";"&SUBSTITUTE(INDEX(Services!$I$2:$I$27,MATCH(D$1,Services!$A$2:$A$27,0))," ","")&";")),"●","") | E9: =IF(ISNUMBER(SEARCH(";"&$A9&";",";"&SUBSTITUTE(INDEX(Services!$I$2:$I$27,MATCH(E$1,Services!$A$2:$A$27,0))," ","")&";")),"●","") | F9: =IF(ISNUMBER(SEARCH(";"&$A9&";",";"&SUBSTITUTE(INDEX(Services!$I$2:$I$27,MATCH(F$1,Services!$A$2:$A$27,0))," ","")&";")),"●","") | G9: =IF(ISNUMBER(SEARCH(";"&$A9&";",";"&SUBSTITUTE(INDEX(Services!$I$2:$I$27,MATCH(G$1,Services!$A$2:$A$27,0))," ","")&";")),"●","") | H9: =IF(ISNUMBER(SEARCH(";"&$A9&";",";"&SUBSTITUTE(INDEX(Services!$I$2:$I$27,MATCH(H$1,Services!$A$2:$A$27,0))," ","")&";")),"●","") | I9: =IF(ISNUMBER(SEARCH(";"&$A9&";",";"&SUBSTITUTE(INDEX(Services!$I$2:$I$27,MATCH(I$1,Services!$A$2:$A$27,0))," ","")&";")),"●","") | J9: =IF(ISNUMBER(SEARCH(";"&$A9&";",";"&SUBSTITUTE(INDEX(Services!$I$2:$I$27,MATCH(J$1,Services!$A$2:$A$27,0))," ","")&";")),"●","") | ... AB9: =IF(ISNUMBER(SEARCH(";"&$A9&";",";"&SUBSTITUTE(INDEX(Services!$I$2:$I$27,MATCH(AB$1,Services!$A$2:$A$27,0))," ","")&";")),"●","") | AC9: =COUNTIF(C9:AB9,"●") -> 1
A10: SP-23 | B10: Opportunity creation (Qualify) | C10: =IF(ISNUMBER(SEARCH(";"&$A10&";",";"&SUBSTITUTE(INDEX(Services!$I$2:$I$27,MATCH(C$1,Services!$A$2:$A$27,0))," ","")&";")),"●","") | D10: =IF(ISNUMBER(SEARCH(";"&$A10&";",";"&SUBSTITUTE(INDEX(Services!$I$2:$I$27,MATCH(D$1,Services!$A$2:$A$27,0))," ","")&";")),"●","") | E10: =IF(ISNUMBER(SEARCH(";"&$A10&";",";"&SUBSTITUTE(INDEX(Services!$I$2:$I$27,MATCH(E$1,Services!$A$2:$A$27,0))," ","")&";")),"●","") | F10: =IF(ISNUMBER(SEARCH(";"&$A10&";",";"&SUBSTITUTE(INDEX(Services!$I$2:$I$27,MATCH(F$1,Services!$A$2:$A$27,0))," ","")&";")),"●","") | G10: =IF(ISNUMBER(SEARCH(";"&$A10&";",";"&SUBSTITUTE(INDEX(Services!$I$2:$I$27,MATCH(G$1,Services!$A$2:$A$27,0))," ","")&";")),"●","") | H10: =IF(ISNUMBER(SEARCH(";"&$A10&";",";"&SUBSTITUTE(INDEX(Services!$I$2:$I$27,MATCH(H$1,Services!$A$2:$A$27,0))," ","")&";")),"●","") | I10: =IF(ISNUMBER(SEARCH(";"&$A10&";",";"&SUBSTITUTE(INDEX(Services!$I$2:$I$27,MATCH(I$1,Services!$A$2:$A$27,0))," ","")&";")),"●","") | J10: =IF(ISNUMBER(SEARCH(";"&$A10&";",";"&SUBSTITUTE(INDEX(Services!$I$2:$I$27,MATCH(J$1,Services!$A$2:$A$27,0))," ","")&";")),"●","") | ... AB10: =IF(ISNUMBER(SEARCH(";"&$A10&";",";"&SUBSTITUTE(INDEX(Services!$I$2:$I$27,MATCH(AB$1,Services!$A$2:$A$27,0))," ","")&";")),"●","") | AC10: =COUNTIF(C10:AB10,"●") -> 4
A11: SP-31 | B11: Demonstration (Evaluate) | C11: =IF(ISNUMBER(SEARCH(";"&$A11&";",";"&SUBSTITUTE(INDEX(Services!$I$2:$I$27,MATCH(C$1,Services!$A$2:$A$27,0))," ","")&";")),"●","") | D11: =IF(ISNUMBER(SEARCH(";"&$A11&";",";"&SUBSTITUTE(INDEX(Services!$I$2:$I$27,MATCH(D$1,Services!$A$2:$A$27,0))," ","")&";")),"●","") | E11: =IF(ISNUMBER(SEARCH(";"&$A11&";",";"&SUBSTITUTE(INDEX(Services!$I$2:$I$27,MATCH(E$1,Services!$A$2:$A$27,0))," ","")&";")),"●","") -> ● | F11: =IF(ISNUMBER(SEARCH(";"&$A11&";",";"&SUBSTITUTE(INDEX(Services!$I$2:$I$27,MATCH(F$1,Services!$A$2:$A$27,0))," ","")&";")),"●","") | G11: =IF(ISNUMBER(SEARCH(";"&$A11&";",";"&SUBSTITUTE(INDEX(Services!$I$2:$I$27,MATCH(G$1,Services!$A$2:$A$27,0))," ","")&";")),"●","") | H11: =IF(ISNUMBER(SEARCH(";"&$A11&";",";"&SUBSTITUTE(INDEX(Services!$I$2:$I$27,MATCH(H$1,Services!$A$2:$A$27,0))," ","")&";")),"●","") | I11: =IF(ISNUMBER(SEARCH(";"&$A11&";",";"&SUBSTITUTE(INDEX(Services!$I$2:$I$27,MATCH(I$1,Services!$A$2:$A$27,0))," ","")&";")),"●","") | J11: =IF(ISNUMBER(SEARCH(";"&$A11&";",";"&SUBSTITUTE(INDEX(Services!$I$2:$I$27,MATCH(J$1,Services!$A$2:$A$27,0))," ","")&";")),"●","") | ... AB11: =IF(ISNUMBER(SEARCH(";"&$A11&";",";"&SUBSTITUTE(INDEX(Services!$I$2:$I$27,MATCH(AB$1,Services!$A$2:$A$27,0))," ","")&";")),"●","") | AC11: =COUNTIF(C11:AB11,"●") -> 3
A12: SP-32 | B12: Census collection (Evaluate) | C12: =IF(ISNUMBER(SEARCH(";"&$A12&";",";"&SUBSTITUTE(INDEX(Services!$I$2:$I$27,MATCH(C$1,Services!$A$2:$A$27,0))," ","")&";")),"●","") | D12: =IF(ISNUMBER(SEARCH(";"&$A12&";",";"&SUBSTITUTE(INDEX(Services!$I$2:$I$27,MATCH(D$1,Services!$A$2:$A$27,0))," ","")&";")),"●","") | E12: =IF(ISNUMBER(SEARCH(";"&$A12&";",";"&SUBSTITUTE(INDEX(Services!$I$2:$I$27,MATCH(E$1,Services!$A$2:$A$27,0))," ","")&";")),"●","") | F12: =IF(ISNUMBER(SEARCH(";"&$A12&";",";"&SUBSTITUTE(INDEX(Services!$I$2:$I$27,MATCH(F$1,Services!$A$2:$A$27,0))," ","")&";")),"●","") | G12: =IF(ISNUMBER(SEARCH(";"&$A12&";",";"&SUBSTITUTE(INDEX(Services!$I$2:$I$27,MATCH(G$1,Services!$A$2:$A$27,0))," ","")&";")),"●","") | H12: =IF(ISNUMBER(SEARCH(";"&$A12&";",";"&SUBSTITUTE(INDEX(Services!$I$2:$I$27,MATCH(H$1,Services!$A$2:$A$27,0))," ","")&";")),"●","") | I12: =IF(ISNUMBER(SEARCH(";"&$A12&";",";"&SUBSTITUTE(INDEX(Services!$I$2:$I$27,MATCH(I$1,Services!$A$2:$A$27,0))," ","")&";")),"●","") | J12: =IF(ISNUMBER(SEARCH(";"&$A12&";",";"&SUBSTITUTE(INDEX(Services!$I$2:$I$27,MATCH(J$1,Services!$A$2:$A$27,0))," ","")&";")),"●","") | ... AB12: =IF(ISNUMBER(SEARCH(";"&$A12&";",";"&SUBSTITUTE(INDEX(Services!$I$2:$I$27,MATCH(AB$1,Services!$A$2:$A$27,0))," ","")&";")),"●","") | AC12: =COUNTIF(C12:AB12,"●") -> 1
